Workbook

Sheet About
A1: Open-ended answers from the three agents: ET-RAG benchmark
A3: Contents
A4: Summary: mean overall judge score per agent for short and long answers, per run, with mean and SD across runs.
A5: Run 1, Run 2, Run 3: for each of the 20 open-ended questions, the expert reference answer and each agent's verbatim answer with its judge scores.
A7: Setup
A8: Corpus: the 10 Alzheimer's disease review papers in 'review papers/'. Questions: 10 short-answer (100-150 words) and 10 long-answer (200-250 words).
A9: Agents: Full Context = Gemini 3.8 Flash reading the complete text of all papers; Cosine RAG = GPT-4o-mini with the top-15 most similar chunks; ET-RAG = GPT-4o-mini with evidence- and recency-reranked chunks plus supplementary abstracts. All at temperature 0.1.
A10: Runs: three independent runs of the same code; answers differ slightly between runs because generation is not fully deterministic.
A11: Scoring: GPT-4o-mini judge (temperature 0.0) rates Completeness, Accuracy, and Relevance from 0 to 1 against the reference answer; Overall = 0.4 × C + 0.4 × A + 0.2 × R. The judge prompt is in the accompanying Word document.
A12: No answer in these runs failed with an API error, so every answer was judged.

Sheet Summary
A1: Overall judge score by agent (mean of the 10 questions in each category)
A3: Short answer
A4: Agent | B4: Run 1 | C4: Run 2 | D4: Run 3 | E4: Mean | F4: SD
A5: Full Context (Gemini 3.8 Flash) | B5: =AVERAGEIFS('Run 1'!I3:I22,'Run 1'!B3:B22,"Short answer") | C5: =AVERAGEIFS('Run 2'!I3:I22,'Run 2'!B3:B22,"Short answer") | D5: =AVERAGEIFS('Run 3'!I3:I22,'Run 3'!B3:B22,"Short answer") | E5: =AVERAGE(B5:D5) | F5: =STDEV(B5:D5)
A6: Cosine RAG (GPT-4o-mini) | B6: =AVERAGEIFS('Run 1'!N3:N22,'Run 1'!B3:B22,"Short answer") | C6: =AVERAGEIFS('Run 2'!N3:N22,'Run 2'!B3:B22,"Short answer") | D6: =AVERAGEIFS('Run 3'!N3:N22,'Run 3'!B3:B22,"Short answer") | E6: =AVERAGE(B6:D6) | F6: =STDEV(B6:D6)
A7: ET-RAG (GPT-4o-mini) | B7: =AVERAGEIFS('Run 1'!S3:S22,'Run 1'!B3:B22,"Short answer") | C7: =AVERAGEIFS('Run 2'!S3:S22,'Run 2'!B3:B22,"Short answer") | D7: =AVERAGEIFS('Run 3'!S3:S22,'Run 3'!B3:B22,"Short answer") | E7: =AVERAGE(B7:D7) | F7: =STDEV(B7:D7)
A9: Long answer
A10: Agent | B10: Run 1 | C10: Run 2 | D10: Run 3 | E10: Mean | F10: SD
A11: Full Context (Gemini 3.8 Flash) | B11: =AVERAGEIFS('Run 1'!I3:I22,'Run 1'!B3:B22,"Long answer") | C11: =AVERAGEIFS('Run 2'!I3:I22,'Run 2'!B3:B22,"Long answer") | D11: =AVERAGEIFS('Run 3'!I3:I22,'Run 3'!B3:B22,"Long answer") | E11: =AVERAGE(B11:D11) | F11: =STDEV(B11:D11)
A12: Cosine RAG (GPT-4o-mini) | B12: =AVERAGEIFS('Run 1'!N3:N22,'Run 1'!B3:B22,"Long answer") | C12: =AVERAGEIFS('Run 2'!N3:N22,'Run 2'!B3:B22,"Long answer") | D12: =AVERAGEIFS('Run 3'!N3:N22,'Run 3'!B3:B22,"Long answer") | E12: =AVERAGE(B12:D12) | F12: =STDEV(B12:D12)
A13: ET-RAG (GPT-4o-mini) | B13: =AVERAGEIFS('Run 1'!S3:S22,'Run 1'!B3:B22,"Long answer") | C13: =AVERAGEIFS('Run 2'!S3:S22,'Run 2'!B3:B22,"Long answer") | D13: =AVERAGEIFS('Run 3'!S3:S22,'Run 3'!B3:B22,"Long answer") | E13: =AVERAGE(B13:D13) | F13: =STDEV(B13:D13)
A15: Overall = 0.4 × Completeness + 0.4 × Accuracy + 0.2 × Relevance, computed per answer on each run sheet. SD is the sample standard deviation across the three runs.

Sheet Run 1
A1: ID | B1: Type | C1: Question | D1: Reference answer (expert) | E1: Full Context (Gemini 3.8 Flash) | J1: Cosine RAG (GPT-4o-mini) | O1: ET-RAG (GPT-4o-mini)
E2: Answer | F2: Completeness | G2: Accuracy | H2: Relevance | I2: Overall | J2: Answer | K2: Completeness | L2: Accuracy | M2: Relevance | N2: Overall | O2: Answer | P2: Completeness | Q2: Accuracy | R2: Relevance | S2: Overall
A3: SA1 | B3: Short answer | C3: What is the role of the Aβ-PET scan in Alzheimer's diagnosis? | D3: Amyloid-beta positron emission tomography (Aβ-PET) enables in vivo visualization of fibrillar β-amyloid plaques, a core pathological hallmark of Alzheimer's disease (AD). Its primary clinical utility lies in improving diagnostic accuracy, particularly in atypical or early-onset presentations and in differentiating AD from non-amyloid dementias. A positive Aβ-PET indicates the presence of amyloid pathology but does not confirm symptomatic AD, as amyloid deposition may occur in cognitively normal individuals. Conversely, a negative scan effectively rules out AD as the cause of cognitive impairment. Aβ-PET is most informative when interpreted alongside clinical findings and other biomarkers (e.g., tau or neurodegeneration markers) within frameworks such as A-T-N. | E3: Aβ-PET scans enable the direct in vivo visualization and quantitative measurement of fibrillar Aβ plaque accumulation and its spatial distribution in the brain (*Alzheimer disease (2021)*; *Recent advances in Alzheimer's disease: mechanisms, clinical trials and new drug development strategies (2024)*). Within the AT(N) diagnostic classification framework, Aβ-PET serves as a core "A" (amyloid) state biomarker to confirm Alzheimer disease (AD) biology (*Alzheimer disease (2021)*). It exhibits approximately 90% sensitivity and specificity in diagnosing AD, detecting pathological brain changes in early preclinical stages years before neurodegeneration occurs (*Recent advances in Alzheimer's disease: mechanisms, clinical trials and new drug development strategies (2024)*; *Alzheimer disease (2021)*). Additionally, Aβ-PET imaging is used in clinical evaluations and trials to confirm amyloid presence, determine patient eligibility for antiamyloid therapies, stage pathology, and monitor therapeutic plaque clearance over time (*Advancements and challenges in antiamyloid therapy for Alzheimer's disease: a comprehensive review (2024)*; *Alzheimer disease (2021)*). | F3: 0.9 | G3: 0.9 | H3: 1 | I3: =0.4*F3+0.4*G3+0.2*H3 | J3: Aβ-PET scans play a crucial role in the diagnosis of Alzheimer's disease (AD) by allowing for the direct visualization of amyloid plaque accumulation in the brain, which is a hallmark of AD pathology. These scans provide quantitative data on the extent and location of amyloid deposition, enhancing diagnostic precision and enabling real-time monitoring of β-amyloidosis progression (Alzheimer disease, 2021). Aβ-PET imaging is particularly useful for staging the disease, differentiating between AD variants, and identifying individuals who may benefit from further diagnostic evaluation (Alzheimer disease, 2021). Additionally, Aβ-PET findings correlate with cerebrospinal fluid (CSF) Aβ levels, although they cannot detect certain Aβ species, such as oligomers (Alzheimer disease, 2021). | K3: 0.8 | L3: 0.9 | M3: 1 | N3: =0.4*K3+0.4*L3+0.2*M3 | O3: The Aβ-PET scan plays a crucial role in the diagnosis of Alzheimer's disease (AD) by providing a non-invasive method to visualize amyloid-beta (Aβ) plaque accumulation in the brain, which is a hallmark of AD pathology. Studies indicate that Aβ-PET exhibits approximately 90% sensitivity and specificity for diagnosing AD, making it a reliable diagnostic tool (Recent advances in Alzheimer's disease: mechanisms, clinical trials and new drug development strategies, 2024). Furthermore, Aβ-PET can detect abnormal brain changes earlier than neurodegeneration, allowing for potential early interventions (Alzheimer disease, 2021). It is particularly useful in differentiating AD from other neurodegenerative diseases, enhancing diagnostic accuracy beyond traditional imaging methods (Recent advances in Alzheimer's disease: mechanisms, clinical trials and new drug development strategies, 2024; Alzheimer disease, 2021). However, Aβ-PET is not universally necessary for all dementia diagnoses, as its utility is more pronounced in specific clinical contexts (Alzheimer disease, 2021). | P3: 0.85 | Q3: 0.9 | R3: 0.95 | S3: =0.4*P3+0.4*Q3+0.2*R3
A4: SA2 | B4: Short answer | C4: How does hearing loss influence AD pathogenesis according to recent studies? | D4: Hearing loss contributes to AD pathogenesis through multiple mechanisms. Reduced auditory input increases cognitive load, requiring compensatory neural processing that may accelerate cognitive decline. It also promotes social isolation and depression, both of which are independent risk factors for dementia. Neurobiologically, hearing loss is associated with cortical reorganization and decreased stimulation, potentially facilitating neurodegeneration. Additionally, shared underlying processes such as vascular dysfunction and chronic inflammation may link hearing impairment and AD. Longitudinal studies suggest that untreated hearing loss is associated with faster cognitive decline, indicating that it is not merely a correlate but may actively contribute to disease progression. | E4: According to *Alzheimer disease (2021)*, midlife hearing loss is identified as a potentially modifiable risk factor associated with an increased risk of later-life dementia, carrying a relative risk between 1.5 and 1.8. Although the text does not describe specific molecular or cellular mechanisms by which hearing loss alters core neuropathology (such as amyloid-β or tau), it highlights that hearing loss is common in patients with Alzheimer disease and can directly exacerbate short-term memory problems. Furthermore, hearing limitations act as a comorbid disability that complicates clinical management and reduces patient and caregiver quality of life. In practice, managing hearing loss in individuals with mild cognitive impairment or dementia is particularly difficult because small hearing aids require careful adjustments; patients frequently misplace or lose the devices, which typically terminates attempts to utilize them. | F4: 0.6 | G4: 0.7 | H4: 0.8 | I4: =0.4*F4+0.4*G4+0.2*H4 | J4: Hearing loss in individuals with Alzheimer's disease (AD) can exacerbate short-term memory problems, complicating the management of cognitive impairment. This auditory deficit poses challenges in treatment, as the use of hearing aids may be hindered by the cognitive difficulties associated with AD, leading to issues such as misplacing devices (Alzheimer disease, 2021). Additionally, hearing loss may represent a confounding disability that complicates the clinical picture of dementia, making it essential to address in the overall management of patients (Alzheimer disease, 2021). | K4: 0.4 | L4: 0.6 | M4: 0.8 | N4: =0.4*K4+0.4*L4+0.2*M4 | O4: Recent studies suggest that hearing loss may influence the pathogenesis of Alzheimer's disease (AD) through several interconnected mechanisms. Hearing impairment is associated with increased neuroinflammation and cognitive decline, which are critical factors in AD progression (Recent advances in Alzheimer's disease: mechanisms, clinical trials and new drug development strategies, 2024). Additionally, myelin damage and oligodendrocyte dysfunction, which are exacerbated by neuroinflammation, can lead to increased amyloid-beta (Aβ) production and impaired clearance, further contributing to AD pathology (Oligodendrocytes in Alzheimer's disease pathophysiology, 2025). The interplay between auditory dysfunction and these neurodegenerative processes highlights the complexity of AD's etiology, suggesting that addressing hearing loss could be a potential avenue for intervention (Alzheimer disease, 2021). However, more research is needed to fully elucidate these relationships. | P4: 0.8 | Q4: 0.9 | R4: 1 | S4: =0.4*P4+0.4*Q4+0.2*R4
A5: SA3 | B5: Short answer | C5: What are the three components of the A-T-N framework? | D5: The A-T-N framework is a biomarker-based classification system for Alzheimer's disease. It consists of three components: 'A' for amyloid-β pathology, typically assessed using Aβ-PET or cerebrospinal fluid (CSF) Aβ42 levels; 'T' for tau pathology, measured via tau-PET or CSF phosphorylated tau; and 'N' for neurodegeneration or neuronal injury, evaluated using structural MRI (atrophy), FDG-PET (hypometabolism), or CSF total tau. This framework allows for a biological definition of AD independent of clinical symptoms and supports disease staging, early detection, and research stratification. However, it does not fully capture additional contributors such as vascular or inflammatory processes. | E5: According to *Alzheimer disease (2021)* and *Recent advances in Alzheimer's disease: mechanisms, clinical trials and new drug development strategies (2024)*, the three biomarker components of the A-T-N [or AT(N)] framework are: 1. **"A" (Amyloid-β deposition):** Biomarkers that proxy Aβ pathology and plaque accumulation, such as cortical retention on Aβ-PET imaging, reduced cerebrospinal fluid (CSF) Aβ42 levels, or a decreased CSF Aβ42/Aβ40 ratio. 2. **"T" (Abnormal or Pathologic Tau):** Biomarkers specific for tau pathology and neurofibrillary tangles, evaluated through tau-PET ligand binding or elevated concentrations of phosphorylated tau (such as CSF p-tau181 or p-tau217). 3. **"N" (Neurodegeneration or Neuronal Injury):** Biomarkers reflecting non-specific progressive neuronal or axonal damage and brain tissue loss, including elevated CSF total tau (t-tau), neurofilament light chain (NfL), glucose hypometabolism on FDG-PET, and regional brain atrophy on structural MRI. | F5: 1 | G5: 1 | H5: 1 | I5: =0.4*F5+0.4*G5+0.2*H5 | J5: The A-T-N framework consists of three components: Aβ (amyloid-beta) deposition, tau pathology, and neurodegeneration. The "A" component refers to amyloid biomarkers, which can be assessed through imaging techniques like PET and cerebrospinal fluid (CSF) analysis. The "T" component involves tau biomarkers, indicating abnormal tau protein levels, while the "N" component encompasses neurodegeneration markers that reflect neuronal injury (Recent advances in Alzheimer's disease: mechanisms, clinical trials and new drug development strategies, 2024; Alzheimer disease, 2021). | K5: 0.8 | L5: 0.9 | M5: 1 | N5: =0.4*K5+0.4*L5+0.2*M5 | O5: The A-T-N framework, proposed by the National Institute on Aging and Alzheimer’s Association (NIA-AA), consists of three components: A (amyloid), T (tau), and N (neurodegeneration). This framework categorizes biomarkers related to Alzheimer's disease (AD) pathology, where "A" refers to the presence of amyloid-beta plaques, "T" indicates the presence of abnormal tau protein, and "N" signifies neurodegeneration, often assessed through neuroimaging or cerebrospinal fluid (CSF) biomarkers (Recent advances in Alzheimer's disease: mechanisms, clinical trials and new drug development strategies, 2024; Alzheimer disease, 2021). The integration of these biomarkers aids in diagnosing and staging AD, providing a comprehensive understanding of the disease's biological underpinnings (Alzheimer disease, 2021). | P5: 0.8 | Q5: 0.9 | R5: 1 | S5: =0.4*P5+0.4*Q5+0.2*R5
A6: SA4 | B6: Short answer | C6: Describe how sleep architecture can predict β-amyloid accumulation. | D6: Sleep architecture, particularly slow-wave sleep (SWS), plays a critical role in regulating β-amyloid levels. During SWS, neuronal activity decreases and glymphatic clearance of metabolic waste increases, facilitating removal of β-amyloid from the brain. Disruption of SWS impairs this clearance mechanism, leading to increased amyloid accumulation, especially in regions such as the medial prefrontal cortex. Experimental studies show that sleep deprivation elevates soluble amyloid levels, while chronic sleep disruption accelerates plaque formation. Additionally, accumulating amyloid can further disrupt sleep-regulating circuits, indicating a bidirectional relationship. Thus, alterations in sleep architecture can both predict and contribute to AD pathology. | E6: According to *Linking activity dyshomeostasis and sleep disturbances in Alzheimer disease (2024)*, specific features of sleep architecture predict amyloid-β (Aβ) pathology. Specifically, lower sleep efficiency predicts subsequently greater Aβ accumulation in presymptomatic individuals. Furthermore, slow-wave deficits specific to lower frequencies (<1 Hz) during non-rapid eye movement (NREM) sleep in the medial prefrontal cortex forecast Aβ accumulation across subsequent years. Physiologically, sleep exhibits reduced neuronal activity and lower interstitial fluid Aβ levels while facilitating clearance through the glymphatic system (*Linking activity dyshomeostasis and sleep disturbances in Alzheimer disease (2024)*; *Alzheimer disease (2021)*). Conversely, wakefulness and sleep deprivation increase extracellular Aβ. Disrupted sleep architecture—marked by sleep fragmentation, attenuated slow-wave activity, and reduced NREM3 and REM sleep duration—breaks down diurnal Aβ fluctuations and clearance mechanisms, predicting elevated Aβ accumulation (*Linking activity dyshomeostasis and sleep disturbances in Alzheimer disease (2024)*). | F6: 0.9 | G6: 0.9 | H6: 1 | I6: =0.4*F6+0.4*G6+0.2*H6 | J6: Sleep architecture can predict β-amyloid (Aβ) accumulation as disturbances in sleep patterns, particularly reduced non-rapid eye movement (NREM) sleep and alterations in sleep spindles, have been associated with increased Aβ levels. Research indicates that sleep disturbances forecast Aβ accumulation over subsequent years, suggesting a bidirectional relationship where impaired sleep may contribute to Aβ deposition (Linking activity dyshomeostasis and sleep disturbances in Alzheimer disease, 2024). Additionally, sleep plays a crucial role in Aβ clearance through the glymphatic system, and disruptions in sleep can compromise this elimination process, further exacerbating Aβ accumulation (Linking activity dyshomeostasis and sleep disturbances in Alzheimer disease, 2024). | K6: 0.8 | L6: 0.9 | M6: 1 | N6: =0.4*K6+0.4*L6+0.2*M6 | O6: Sleep architecture can predict β-amyloid accumulation through its impact on neuronal activity and homeostasis. Disruptions in sleep, particularly in non-rapid eye movement (NREM) sleep, have been linked to increased β-amyloid levels. For instance, sleep disturbances forecast β-amyloid accumulation over subsequent years (Winer et al., 2020). Additionally, sleep facilitates the clearance of β-amyloid via the glymphatic system, which is compromised in Alzheimer's disease (Holth et al., 2019; Xie et al., 2013). Changes in sleep architecture, such as reduced slow-wave activity and altered sleep spindle density, are observed in individuals with mild cognitive impairment and Alzheimer's disease, preceding significant cognitive decline (Mander et al., 2015; Gorgoni et al., 2016). Thus, sleep architecture serves as a critical predictor of β-amyloid dynamics and Alzheimer's disease progression (Linking activity dyshomeostasis and sleep disturbances in Alzheimer disease, 2024). | P6: 0.85 | Q6: 0.9 | R6: 1 | S6: =0.4*P6+0.4*Q6+0.2*R6
A7: SA5 | B7: Short answer | C7: What is the significance of the Mediterranean diet in AD research? | D7: The Mediterranean diet is associated with reduced risk of cognitive decline and Alzheimer's disease through multiple protective mechanisms. It emphasizes consumption of fruits, vegetables, whole grains, legumes, fish, and olive oil, providing antioxidants and anti-inflammatory compounds that reduce oxidative stress and neuroinflammation. The diet also supports vascular health, which is critical for maintaining cerebral perfusion and reducing neurodegenerative risk. Epidemiological studies demonstrate that higher adherence is linked to slower cognitive decline and lower incidence of AD. However, interpretation is complicated by confounding lifestyle factors and variability in dietary assessment, limiting definitive causal conclusions. | E7: In Alzheimer disease (AD) research, the Mediterranean diet (MeDi) is recognized as a protective nutritional model rich in monounsaturated and polyunsaturated fatty acids, antioxidants, vitamins, and minerals, while low in saturated fats (*Oxidative damage in neurodegeneration: roles in the pathogenesis and progression of Alzheimer disease*, 2024). Epidemiological studies and clinical trials demonstrate that higher adherence to the MeDi correlates with a reduced risk of incident AD, lower progression rates from mild cognitive impairment to AD, improved cognitive performance (such as in the PREDIMED-NAVARRA trial), and decreased mortality (*Oxidative damage in neurodegeneration: roles in the pathogenesis and progression of Alzheimer disease*, 2024). Furthermore, unlike pro-inflammatory diets, the MeDi helps reduce neuroinflammation and brain atrophy, offering resilience against oxidative stress and hallmark pathologies (*Neuroinflammation in Alzheimer disease*, 2025; *Oxidative damage in neurodegeneration: roles in the pathogenesis and progression of Alzheimer disease*, 2024). | F7: 0.9 | G7: 0.9 | H7: 1 | I7: =0.4*F7+0.4*G7+0.2*H7 | J7: The Mediterranean diet (MeDi) has been associated with a reduced risk of Alzheimer's disease (AD) and cognitive decline, as it includes essential nutrients and protective components while excluding harmful foods linked to AD risk (Oxidative damage in neurodegeneration, 2024). Various studies, including cross-sectional and randomized controlled trials, have shown that adherence to the MeDi correlates with improved cognitive outcomes and lower mortality in AD patients (Oxidative damage in neurodegeneration, 2024). However, some studies have reported no significant association between MeDi adherence and AD risk, indicating the need for further research to clarify these relationships (Oxidative damage in neurodegeneration, 2024). Overall, the MeDi represents a promising dietary approach in AD research, highlighting the importance of nutrition in modulating disease progression and cognitive health. | K7: 0.8 | L7: 0.8 | M7: 1 | N7: =0.4*K7+0.4*L7+0.2*M7 | O7: The Mediterranean diet (MeDi) is significant in Alzheimer's disease (AD) research due to its association with reduced risk and progression of cognitive decline. Studies indicate that adherence to the MeDi correlates with lower incidence rates of AD and improved cognitive outcomes in at-risk populations (Garcia-Casares et al., 2021; Ballarini et al., 2021). The MeDi is rich in protective nutrients and low in harmful fats, which may mitigate neuroinflammation and oxidative stress, both implicated in AD pathology (Oxidative damage in neurodegeneration, 2024). However, some studies report conflicting results, suggesting that not all research supports a strong link between MeDi adherence and AD risk (Oxidative damage in neurodegeneration, 2024). Overall, the MeDi represents a promising dietary approach for cognitive health, warranting further investigation (Neuroinflammation in Alzheimer disease, 2025). | P7: 0.8 | Q7: 0.9 | R7: 1 | S7: =0.4*P7+0.4*Q7+0.2*R7
A8: SA6 | B8: Short answer | C8: Explain the role of tau-PET imaging. | D8: Tau-PET imaging allows in vivo visualization of neurofibrillary tangles composed of hyperphosphorylated tau protein. Unlike amyloid deposition, which occurs early and plateaus, tau accumulation closely correlates with neuronal loss and cognitive impairment. Tau-PET provides spatial information that aligns with disease progression patterns, such as Braak staging. It is particularly useful for assessing disease severity, predicting clinical symptoms, and distinguishing Alzheimer's subtypes based on regional tau distribution. As a result, tau-PET has become an important tool in both research and clinical trials, especially for monitoring disease progression and therapeutic response. | E8: Tau positron emission tomography (tau-PET) imaging visualizes and quantifies the regional abundance, spatial distribution, and spread of tauopathy in vivo (*Alzheimer disease (2021)*). Within the A-T-N classification framework, tau-PET functions as a staging biomarker reflecting disease severity, as its binding topography correlates strongly with cognitive impairment, fluorodeoxyglucose (FDG) hypometabolism, and distinct clinical phenotypes such as amnestic, visual, language, or dysexecutive syndromes (*Alzheimer disease (2021)*). Tau-PET specifically differentiates Alzheimer disease dementia from other neurodegenerative disorders with superior diagnostic accuracy over MRI markers, and it robustly predicts subsequent cognitive decline in both asymptomatic and symptomatic individuals (*Alzheimer disease (2021)*; *Recent advances in Alzheimer's disease: mechanisms, clinical trials and new drug development strategies (2024)*). Furthermore, tau-PET monitors longitudinal pathological progression and serves as an important outcome measure in clinical trials evaluating emerging disease-modifying therapies (*Advancements and challenges in antiamyloid therapy for Alzheimer's disease: a comprehensive review (2024)*; *Recent advances in Alzheimer's disease: mechanisms, clinical trials and new drug development strategies (2024)*). | F8: 0.9 | G8: 0.9 | H8: 1 | I8: =0.4*F8+0.4*G8+0.2*H8 | J8: Tau-PET imaging is a valuable tool for detecting tauopathy, which is closely associated with Alzheimer's disease (AD). It provides insights into the regional accumulation of tau protein, correlating strongly with cognitive performance and mapping onto various clinical phenotypes of AD (Alzheimer disease, 2021). The abnormalities detected by tau-PET are predictive of subsequent cognitive decline in both asymptomatic and symptomatic individuals, making it sensitive to the progression of tau pathology over time (Alzheimer disease, 2021). Additionally, tau-PET imaging can differentiate AD from other neurodegenerative disorders, demonstrating higher diagnostic accuracy compared to traditional MRI markers (Recent advances in Alzheimer's disease: mechanisms, clinical trials and new drug development strategies, 2024). | K8: 0.8 | L8: 0.9 | M8: 1 | N8: =0.4*K8+0.4*L8+0.2*M8 | O8: Tau-PET imaging plays a crucial role in diagnosing and monitoring Alzheimer's disease (AD) by detecting neurofibrillary tangles, which are indicative of tau pathology. This imaging modality is particularly valuable as it can differentiate AD from other neurodegenerative disorders, showing higher diagnostic accuracy than traditional MRI markers (Alzheimer disease, 2021). Tau-PET binding patterns correlate strongly with cognitive performance and can predict cognitive decline in both symptomatic and asymptomatic individuals (Alzheimer disease, 2021; Recent advances in Alzheimer's disease, 2024). Furthermore, tau accumulation occurs closer to the onset of cognitive symptoms compared to amyloid deposition, making tau-PET a critical tool for early intervention strategies (Alzheimer disease, 2021). Overall, tau-PET imaging enhances our understanding of AD pathology and supports the development of targeted therapies (Neuroinflammation in Alzheimer disease, 2025). | P8: 0.85 | Q8: 0.9 | R8: 1 | S8: =0.4*P8+0.4*Q8+0.2*R8
A9: SA7 | B9: Short answer | C9: Why are hearing interventions considered in dementia prevention? | D9: Hearing interventions, such as hearing aids or cochlear implants, are considered in dementia prevention because they address a modifiable risk factor. By restoring auditory input, these interventions reduce cognitive load and improve communication, which may preserve cognitive reserve. They also help mitigate social isolation and depression, both associated with increased dementia risk. Emerging evidence suggests that individuals who use hearing aids experience slower cognitive decline compared to those with untreated hearing loss. Although causality is still being investigated, hearing interventions represent a practical and scalable strategy for potentially delaying or reducing Alzheimer's disease risk. | E9: Hearing interventions are considered in dementia prevention because hearing loss occurring in midlife is recognized as a potentially modifiable risk factor associated with an increased risk of developing later-life dementia, with relative risks ranging between 1.5 and 1.8 (*Alzheimer disease*, 2021). Additionally, hearing loss is common among individuals with Alzheimer disease and directly exacerbates short-term memory problems (*Alzheimer disease*, 2021). Beyond worsening cognitive difficulties, hearing limitations represent a confounding comorbidity that negatively affects the daily functioning, overall quality of life, and emotional well-being of both patients and their caregivers (*Alzheimer disease*, 2021). Consequently, targeting hearing loss through interventions such as hearing aids addresses an important modifiable contributor to dementia risk and helps alleviate sensory deficits that compound cognitive decline and complicate patient management (*Alzheimer disease*, 2021). | F9: 0.8 | G9: 0.9 | H9: 1 | I9: =0.4*F9+0.4*G9+0.2*H9 | J9: Hearing loss is common in patients with Alzheimer's disease (AD) and can exacerbate short-term memory problems, presenting a management challenge due to the difficulties in adjusting hearing aids for individuals with cognitive impairment (Alzheimer disease, 2021). Addressing hearing loss may improve communication and social engagement, which are crucial for maintaining cognitive function and quality of life in individuals at risk for dementia (Alzheimer disease, 2021). Therefore, interventions for hearing loss are considered important in the context of dementia prevention and management. | K9: 0.7 | L9: 0.8 | M9: 0.9 | N9: =0.4*K9+0.4*L9+0.2*M9 | O9: Hearing interventions are considered in dementia prevention due to their potential role in mitigating cognitive decline. Research indicates that lifestyle factors, including sensory health, can influence dementia risk. For instance, the FINGER study demonstrated that multidomain interventions, which may include sensory training, can improve cognitive outcomes in at-risk populations (Alzheimer disease, 2021). Additionally, addressing hearing loss may enhance social engagement and cognitive stimulation, which are protective factors against dementia (Oxidative damage in neurodegeneration, 2024). However, while the evidence supports the importance of lifestyle modifications, including hearing interventions, the specific impact of these interventions on dementia prevention remains an area requiring further investigation (Recent advances in Alzheimer's disease, 2024). | P9: 0.8 | Q9: 0.9 | R9: 1 | S9: =0.4*P9+0.4*Q9+0.2*R9
A10: SA8 | B10: Short answer | C10: How might gut microbiota influence AD? | D10: Gut microbiota may influence Alzheimer's disease through the gut-brain axis. Dysbiosis can lead to systemic inflammation, increasing circulating cytokines that may affect the brain and promote neuroinflammation. Microbial metabolites, such as short-chain fatty acids, can modulate neuronal function and immune responses. Additionally, microbial amyloids may contribute to cross-seeding of human amyloid proteins, potentially accelerating aggregation. Increased gut permeability may further exacerbate inflammatory processes. While animal studies provide strong mechanistic evidence, human studies remain largely associative, and therapeutic approaches targeting the microbiome are still under investigation. | E10: The gut microbiota influences Alzheimer disease (AD) via the microbiota-gut-brain axis through immune, metabolic, and barrier-modulatory pathways. As detailed in *Recent advances in Alzheimer's disease: mechanisms, clinical trials and new drug development strategies (2024)*, gut dysbiosis compromises the intestinal epithelial barrier, enabling bacterial components and inflammatory mediators to enter circulation, breach the blood–brain barrier (BBB), and trigger microglial activation and neuroinflammation. According to *Immune Activation in Alzheimer Disease (2024)*, transplanting AD patient microbiota into mice activates intestinal NLRP3 inflammasomes, circulating cytokines (IL-1β, IL-18, TNF-α) to the brain and activating microglia. Furthermore, microbial short-chain fatty acids (SCFAs) promote C/EBPβ activation, tau hyperphosphorylation, and gliosis. *Neuroinflammation in Alzheimer disease (2025)* notes that the microbiome regulates microglial maturation and BBB permeability. While healthy metabolites (such as tryptophan derivatives and bile acids) suppress neuroinflammation via aryl hydrocarbon receptor and TGR5 signaling, fecal transplants from AD donors directly induce AD-like cognitive deficits. | F10: 0.9 | G10: 0.9 | H10: 1 | I10: =0.4*F10+0.4*G10+0.2*H10 | J10: Gut microbiota may influence Alzheimer's disease (AD) through several mechanisms, including the modulation of immune responses and the integrity of the blood-brain barrier (BBB). Dysbiosis can lead to systemic inflammation, allowing inflammatory mediators to cross the BBB and exacerbate neuroinflammation in the brain (Neuroinflammation in Alzheimer disease, 2025). Additionally, microbial metabolites, such as short-chain fatty acids, can affect microglial function and promote an anti-inflammatory phenotype, potentially mitigating AD pathology (Neuroinflammation in Alzheimer disease, 2025). Furthermore, alterations in gut microbiota composition have been linked to cognitive deficits and amyloid pathology in mouse models of AD (Recent advances in Alzheimer's disease, 2024). | K10: 0.8 | L10: 0.9 | M10: 1 | N10: =0.4*K10+0.4*L10+0.2*M10 | O10: Gut microbiota may influence Alzheimer's disease (AD) through several mechanisms, primarily involving neuroinflammation and immune modulation. Research indicates that the gut microbiome can shape microglial responses to pathological insults, with studies showing that fecal transplantation from healthy donors can reduce AD-like symptoms in mouse models (Neuroinflammation in Alzheimer disease, 2025). Dysbiosis, or an imbalance in gut microbiota, can lead to systemic inflammation, allowing inflammatory mediators to cross the blood-brain barrier (BBB) and exacerbate neuroinflammation, which is implicated in AD pathology (Recent advances in Alzheimer's disease, 2024). Additionally, microbial metabolites, such as short-chain fatty acids, may modulate microglial activity and influence neuroinflammatory pathways (Neuroinflammation in Alzheimer disease, 2025). However, the precise mechanisms by which gut microbiota alterations affect AD progression remain to be fully elucidated (Neuroinflammation in Alzheimer disease, 2025). | P10: 0.85 | Q10: 0.9 | R10: 1 | S10: =0.4*P10+0.4*Q10+0.2*R10
A11: SA9 | B11: Short answer | C11: What is the purpose of using Mendelian Randomization in AD studies? | D11: Mendelian Randomization (MR) is used in Alzheimer's research to infer causal relationships between risk factors and disease outcomes. It employs genetic variants as instrumental variables, which are randomly assigned at conception and thus less susceptible to confounding and reverse causation. MR can help determine whether observed associations—such as those involving cholesterol, education, or inflammation—are likely to be causal. This approach strengthens epidemiological findings and informs potential intervention targets. However, its validity depends on key assumptions, including the absence of pleiotropic effects, which can complicate interpretation. | E11: NOT_COVERED: This information is not covered in the uploaded research papers. | F11: 0 | G11: 0 | H11: 0 | I11: =0.4*F11+0.4*G11+0.2*H11 | J11: The purpose of using Mendelian Randomization in Alzheimer's disease (AD) studies is to assess the causal relationships between modifiable risk factors and AD outcomes by leveraging genetic variants as instrumental variables. This approach helps to minimize confounding factors and biases that can affect observational studies, providing more robust evidence for the role of specific risk factors in the pathogenesis of AD (Alzheimer disease, 2021). By identifying genetic variants associated with risk factors, researchers can infer the potential impact of these factors on AD development and progression, thus guiding preventive strategies and therapeutic interventions (Recent advances in Alzheimer’s disease mechanisms clinical trials and new drug development strategies, 2024). | K11: 0.85 | L11: 0.9 | M11: 1 | N11: =0.4*K11+0.4*L11+0.2*M11 | O11: Mendelian Randomization (MR) is employed in Alzheimer's disease (AD) studies to elucidate causal relationships between genetic variants and disease outcomes, thereby addressing the complexities of AD's multifactorial etiology. This approach leverages genetic variants as instrumental variables to infer causality, minimizing confounding factors that often complicate observational studies (Zhang et al., 2024). MR can help identify potential modifiable risk factors and biological pathways involved in AD, which is crucial given the intricate interplay of genetic, environmental, and lifestyle factors influencing disease progression (Zhang et al., 2024; Oxidative damage in neurodegeneration, 2024). Furthermore, MR can assist in validating findings from genome-wide association studies (GWAS) by providing insights into the functional implications of identified genetic loci (Zhang et al., 2024). Overall, MR enhances the understanding of AD mechanisms and informs potential therapeutic targets. | P11: 0.9 | Q11: 0.9 | R11: 1 | S11: =0.4*P11+0.4*Q11+0.2*R11
A12: SA10 | B12: Short answer | C12: What is the effect of chronic hypoxia on Alzheimer's pathology? | D12: Chronic hypoxia contributes to Alzheimer's pathology through several mechanisms. Reduced oxygen levels promote amyloidogenic processing of amyloid precursor protein, increasing β-amyloid production. Hypoxia also enhances tau phosphorylation via activation of stress-related kinases. In addition, it induces oxidative stress, mitochondrial dysfunction, and neuroinflammation, all of which exacerbate neuronal damage. Vascular dysfunction and blood-brain barrier disruption further compound these effects. Conditions such as sleep apnea exemplify chronic hypoxia and have been associated with increased AD risk, highlighting its role as both a contributing factor and a potential therapeutic target. | E12: Although “chronic hypoxia” is not explicitly differentiated from general hypoxia in the provided texts, the papers document several consequences of hypoxia, hypoperfusion, and ischemic stress on Alzheimer’s disease (AD) pathology: - **Increased Amyloid-β (Aβ) Generation:** Disruption of the blood–brain barrier (BBB) causes ischemic/hypoxic brain damage, which increases Aβ production; in addition, hypoxic markers accumulate in the brains of AD patients and animal models (*Neuroinflammation in Alzheimer disease (2025)*; *Recent advances in Alzheimer's disease: mechanisms, clinical trials and new drug development strategies (2024)*). - **Oligodendrocyte and Myelin Damage:** Deep white matter regions are prone to hypoperfusion and reduced oxygenation. Oligodendrocytes and myelin sheaths are especially vulnerable to hypoxia-induced oxidative stress, exacerbating white matter pathology (*Oligodendrocytes in Alzheimer's disease pathophysiology (2025)*). - **Mitochondrial Dysfunction and Mitophagy:** Hypoxia-induced cellular damage triggers the selective removal and renewal of damaged mitochondria via autophagic machinery (*Oxidative damage in neurodegeneration: roles in the pathogenesis and progression of Alzheimer disease (2024)*). | F12: 0.7 | G12: 0.8 | H12: 0.9 | I12: =0.4*F12+0.4*G12+0.2*H12 | J12: Chronic hypoxia exacerbates Alzheimer's pathology by increasing oxidative stress and promoting myelin damage, particularly in oligodendrocytes. This condition leads to impaired nerve conduction and neuronal support functions, contributing to cognitive decline (Oligodendrocytes in Alzheimer's disease pathophysiology, 2025). Additionally, hypoperfusion associated with aging and cerebral amyloid angiopathy further compromises blood flow and oxygenation in white matter, making it more susceptible to degeneration (Oligodendrocytes in Alzheimer's disease pathophysiology, 2025). The accumulation of toxic Aβ peptides in the brain may also be influenced by hypoxic conditions, leading to accelerated neurodegeneration (Oxidative damage in neurodegeneration: roles in the pathogenesis and progression of Alzheimer disease, 2024). | K12: 0.7 | L12: 0.8 | M12: 1 | N12: =0.4*K12+0.4*L12+0.2*M12 | O12: Chronic hypoxia appears to exacerbate Alzheimer's pathology through several mechanisms, primarily involving oxidative stress and vascular dysfunction. Oligodendrocytes, which are crucial for myelin maintenance, are particularly vulnerable to hypoxia-induced oxidative stress, leading to myelin damage and contributing to neurodegeneration (Oligodendrocytes in Alzheimer's disease pathophysiology, 2025). Additionally, hypoxia can impair cerebral blood flow, which is linked to amyloid accumulation and neuroinflammation, further aggravating Alzheimer's pathology (Oxidative damage in neurodegeneration: roles in the pathogenesis and progression of Alzheimer disease, 2024). The interplay between hypoxia, oxidative stress, and amyloid pathology suggests a complex relationship that may accelerate cognitive decline in Alzheimer's disease (Recent advances in Alzheimer's disease: mechanisms, clinical trials and new drug development strategies, 2024). Overall, chronic hypoxia is implicated in worsening Alzheimer's pathology through oxidative damage and vascular dysfunction. | P12: 0.8 | Q12: 0.9 | R12: 1 | S12: =0.4*P12+0.4*Q12+0.2*R12
A13: LA1 | B13: Long answer | C13: Discuss the bidirectional relationship between sleep disturbances and Alzheimer's disease and how it can influence future therapeutic strategies. | D13: Sleep disturbances and Alzheimer's disease (AD) are linked through a bidirectional relationship in which each exacerbates the other. On one hand, disrupted sleep—particularly reduced slow-wave sleep (SWS)—impairs glymphatic clearance of β-amyloid, leading to its accumulation in the brain. Experimental and longitudinal studies show that sleep deprivation increases soluble amyloid levels and accelerates plaque deposition. On the other hand, AD pathology itself disrupts neural circuits involved in sleep regulation, including the hypothalamus and brainstem, resulting in fragmented sleep and circadian rhythm disturbances. Tau pathology further contributes by impairing neuronal networks responsible for sleep stability. This feedback loop suggests that sleep disruption is both a risk factor and an early symptom of AD. Therapeutically, this has important implications. Interventions such as cognitive behavioral therapy for insomnia (CBT-I), pharmacological agents targeting sleep pathways, and neuromodulation techniques to enhance SWS may help reduce amyloid burden or slow disease progression. However, current evidence is largely associative, and causality remains to be firmly established. Longitudinal and interventional studies are needed to determine whether improving sleep can meaningfully alter disease trajectory. | E13: The relationship between sleep disturbances and Alzheimer’s disease (AD) is bidirectional. Sleep deprivation and reduced sleep efficiency elevate extracellular amyloid-β (Aβ) and tau accumulation in humans and animal models, partly by impairing sleep-dependent glymphatic clearance (*Linking activity dyshomeostasis and sleep disturbances in Alzheimer disease (2024)*; *Alzheimer disease (2021)*). Conversely, pathological Aβ and tau disrupt sleep–wake architecture, reducing slow-wave (NREM3) and REM sleep while increasing fragmentation (*Linking activity dyshomeostasis and sleep disturbances in Alzheimer disease (2024)*; *Updates on mouse models of Alzheimer's disease (2024)*). Crucially, early Aβ pathology causes firing rate dyshomeostasis, triggering network hyperexcitability and subclinical epileptiform spikes predominantly during low-arousal states such as sleep (*Linking activity dyshomeostasis and sleep disturbances in Alzheimer disease (2024)*). Paradoxically, presymptomatic sleep curtailment may represent an adaptive physiological mechanism that restricts this sleep-confined hyperexcitability and prevents seizures (*Linking activity dyshomeostasis and sleep disturbances in Alzheimer disease (2024)*). This dynamic profoundly impacts future therapeutics. Distinguishing between drivers of pathology and compensatory responses is critical: administering hypnotics to artificially prolong sleep without resolving underlying hyperexcitability poses significant risks and could accelerate cognitive decline (*Linking activity dyshomeostasis and sleep disturbances in Alzheimer disease (2024)*). Consequently, future disease-modifying strategies focus on restoring activity homeostasis during sleep. Promising approaches include targeting firing set points via mitochondrial dihydroorotate dehydrogenase inhibition, activating mitochondrial calcium uniporters, modulating melanin-concentrating hormone signalling, and applying deep brain stimulation to the thalamic nucleus reuniens or prefrontal cortex to abrogate hyperexcitability (*Linking activity dyshomeostasis and sleep disturbances in Alzheimer disease (2024)*). | F13: 0.9 | G13: 0.9 | H13: 1 | I13: =0.4*F13+0.4*G13+0.2*H13 | J13: The relationship between sleep disturbances and Alzheimer's disease (AD) is bidirectional, with each influencing the other. Sleep disturbances in AD patients manifest as reduced duration of NREM and REM sleep, increased wakefulness, and fragmented circadian rhythms (Linking activity dyshomeostasis and sleep disturbances in Alzheimer disease, 2024). These alterations in sleep architecture are associated with cognitive impairments, as decreased NREM3 and REM sleep correlate with memory deficits (Linking activity dyshomeostasis and sleep disturbances in Alzheimer disease, 2024). Furthermore, sleep is crucial for Aβ clearance, and disruptions in sleep can lead to increased Aβ levels, exacerbating AD pathology (Linking activity dyshomeostasis and sleep disturbances in Alzheimer disease, 2024). Conversely, the accumulation of Aβ during the presymptomatic phase of AD impairs homeostatic mechanisms, leading to hyperexcitability during sleep (Linking activity dyshomeostasis and sleep disturbances in Alzheimer disease, 2024). This hyperexcitability can further disrupt sleep patterns, creating a vicious cycle that accelerates cognitive decline. As the disease progresses, adaptive responses to mitigate hyperexcitability, such as sleep disturbances, may become maladaptive, leading to significant neurodegeneration and memory loss (Linking activity dyshomeostasis and sleep disturbances in Alzheimer disease, 2024). Understanding this bidirectional relationship is essential for developing future therapeutic strategies. Interventions targeting sleep homeostasis may need to be carefully balanced with the management of hyperexcitability to avoid exacerbating cognitive decline (Linking activity dyshomeostasis and sleep disturbances in Alzheimer disease, 2024). By addressing both sleep disturbances and underlying AD pathology, it may be possible to enhance cognitive resilience and slow disease progression. | K13: 0.85 | L13: 0.9 | M13: 0.95 | N13: =0.4*K13+0.4*L13+0.2*M13 | O13: The bidirectional relationship between sleep disturbances and Alzheimer's disease (AD) is increasingly recognized as a critical factor influencing disease progression and potential therapeutic strategies. Sleep disturbances, such as reduced slow-wave sleep and altered sleep architecture, are prevalent in individuals with AD and may exacerbate cognitive decline (Zhang et al., 2022). Conversely, the accumulation of amyloid-β (Aβ) and tau proteins disrupts sleep homeostasis, leading to hyperexcitability in neuronal circuits during sleep, which can further impair memory consolidation (Mander et al., 2020; Wang & Holtzman, 2020). Research suggests that sleep disturbances may serve as an adaptive response to mitigate hyperexcitability in the presymptomatic stages of AD (Kam et al., 2024). This interplay indicates that addressing sleep quality could be a viable therapeutic target. For instance, pharmacological interventions aimed at enhancing sleep quality or restoring sleep architecture may help delay the onset of cognitive symptoms by improving activity homeostasis in the brain (Lucey et al., 2018; Holth et al., 2019). Future therapeutic strategies could focus on developing treatments that not only target amyloid and tau pathology but also incorporate sleep regulation mechanisms. This dual approach may enhance cognitive resilience and slow disease progression, as suggested by recent findings on the role of sleep in regulating Aβ dynamics (Roh et al., 2012; Winer et al., 2020). Overall, understanding the complex relationship between sleep and AD is crucial for identifying innovative treatment pathways. | P13: 0.85 | Q13: 0.9 | R13: 1 | S13: =0.4*P13+0.4*Q13+0.2*R13
A14: LA2 | B14: Long answer | C14: Evaluate the A-T-N biomarker framework and its utility in staging Alzheimer's disease. | D14: The A-T-N framework represents a major advancement in Alzheimer's disease (AD) research by providing a biomarker-based classification system independent of clinical symptoms. It categorizes pathology into amyloid (A), tau (T), and neurodegeneration (N), enabling detection of preclinical disease stages and improving diagnostic precision. This framework has enhanced research standardization and facilitated stratification of participants in clinical trials. Despite its strengths, the A-T-N framework has limitations. It does not account for other important pathological processes such as vascular dysfunction, neuroinflammation, or synaptic loss, which are increasingly recognized as contributors to AD. Additionally, biomarker positivity does not always correspond to clinical symptoms, complicating interpretation and clinical decision-making. Practical challenges include high costs, limited accessibility, and invasiveness of current biomarker assessments. Future directions include expanding the framework to incorporate additional domains and developing blood-based biomarkers to improve scalability. While not comprehensive, the A-T-N framework remains a foundational tool for understanding disease progression and guiding research. | E14: The A-T-N (or AT(N)) framework, established by the National Institute on Aging–Alzheimer's Association (NIA-AA), biologically classifies Alzheimer disease (AD) across three biomarker categories: amyloid-β deposition (“A”), pathologic tau (“T”), and neurodegeneration or neuronal injury (“N”) (*Alzheimer disease (2021)*; *Recent advances in Alzheimer's disease: mechanisms, clinical trials and new drug development strategies (2024)*). “A” is measured via Aβ-PET or reduced CSF Aβ42 (or Aβ42/Aβ40 ratio); “T” via CSF phosphorylated tau (p-tau181, p-tau217) or tau-PET; and “N” via structural MRI, 18FDG-PET, CSF total tau, or neurofilament light chain (NfL) (*Alzheimer disease (2021)*; *Recent advances in Alzheimer's disease: mechanisms, clinical trials and new drug development strategies (2024)*). For disease staging, the framework differentiates “state” from “stage” biomarkers (*Alzheimer disease (2021)*). While “A” markers confirm whether an individual is on the AD biological continuum, cerebral Aβ accumulation begins 10–20 years prior to clinical symptoms and decelerates near onset, limiting its capacity to stage active clinical severity (*Alzheimer disease (2021)*). Conversely, tau-PET, FDG-PET, and “N” metrics function as stage biomarkers that monitor disease severity; isocortical tau expansion and progressive hypometabolism correlate directly with synaptic failure and cognitive decline (*Alzheimer disease (2021)*; *Recent advances in Alzheimer's disease: mechanisms, clinical trials and new drug development strategies (2024)*). However, the framework presents critical limitations: “N” markers lack AD specificity because regional atrophy and hypometabolism are frequently confounded by co-occurring pathologies, including cerebrovascular disease and frontotemporal lobar degeneration (*Alzheimer disease (2021)*; *Recent advances in Alzheimer's disease: mechanisms, clinical trials and new drug development strategies (2024)*). Furthermore, while fluid p-tau provides binary diagnostic classification, quantitative tau-PET is necessary to delineate spatial distribution and predict cognitive deterioration (*Alzheimer disease (2021)*; *Recent advances in Alzheimer's disease: mechanisms, clinical trials and new drug development strategies (2024)*). | F14: 0.85 | G14: 0.9 | H14: 1 | I14: =0.4*F14+0.4*G14+0.2*H14 | J14: The A-T-N biomarker framework is a significant advancement in the diagnosis and staging of Alzheimer's disease (AD), categorizing biomarkers into three distinct groups: amyloid (A), tau (T), and neurodegeneration (N). This framework allows for a more nuanced understanding of AD pathology, moving beyond traditional diagnostic methods that relied heavily on clinical symptoms and post-mortem evaluations (Alzheimer disease, 2021). The integration of antemortem biomarkers has enhanced diagnostic certainty, enabling clinicians to classify individuals within the AD spectrum more accurately. Imaging techniques such as amyloid PET and tau PET are central to the A-T-N framework, providing insights into the accumulation of amyloid plaques and tau tangles, respectively. Studies indicate that amyloid PET exhibits high sensitivity and specificity for diagnosing AD, while tau PET can differentiate AD dementia from other neurodegenerative diseases with greater accuracy than MRI (Recent advances in Alzheimer’s disease mechanisms clinical trials and new drug development strategies, 2024). This capability is crucial for early intervention, as tau PET may detect abnormal brain changes prior to neurodegeneration. Furthermore, cerebrospinal fluid (CSF) biomarkers, including Aβ42 and phosphorylated tau (p-tau181), are integral to the A-T-N framework. These biomarkers have been validated for their diagnostic utility and can indicate the severity of AD pathology (Alzheimer disease, 2021). The combination of these biomarkers not only aids in staging the disease but also enhances the understanding of its biological underpinnings, facilitating more targeted therapeutic approaches. Overall, the A-T-N framework represents a comprehensive strategy for assessing and managing Alzheimer's disease. | K14: 0.85 | L14: 0.9 | M14: 1 | N14: =0.4*K14+0.4*L14+0.2*M14 | O14: The A-T-N biomarker framework, proposed by the National Institute on Aging and Alzheimer’s Association (NIA-AA), categorizes Alzheimer's disease (AD) biomarkers into three components: A (amyloid deposition), T (tau pathology), and N (neurodegeneration). This framework enhances the staging of AD by providing a structured approach to classify individuals along the disease spectrum based on biological markers (Recent advances in Alzheimer's disease: mechanisms, clinical trials and new drug development strategies, 2024). The utility of the A-T-N framework is evident in its ability to integrate various biomarker types, including cerebrospinal fluid (CSF) and imaging biomarkers. For instance, CSF levels of Aβ42 and phosphorylated tau (P-tau181) are recognized as specific indicators of AD pathology, while neurofilament light chain (NfL) serves as a general marker of neurodegeneration (Alzheimer disease, 2021). Studies indicate that tau PET imaging provides higher diagnostic accuracy than MRI markers and can differentiate AD from other neurodegenerative diseases (Recent advances in Alzheimer's disease: mechanisms, clinical trials and new drug development strategies, 2024). However, limitations exist; for example, the A-T-N biomarkers may not fully distinguish AD from other conditions with overlapping features, such as frontotemporal degeneration (Recent advances in Alzheimer's disease: mechanisms, clinical trials and new drug development strategies, 2024). Additionally, discrepancies between CSF and imaging biomarker results highlight the need for comprehensive evaluations that combine clinical assessments with biomarker data (Alzheimer disease, 2021). Overall, while the A-T-N framework significantly advances our understanding and staging of AD, ongoing research is essential to refine its application and address its limitations. | P14: 0.85 | Q14: 0.9 | R14: 1 | S14: =0.4*P14+0.4*Q14+0.2*R14
